<?xml version="1.0" encoding="utf-8"?>
<!-- This URDF was automatically created by SolidWorks to URDF Exporter! Originally created by Stephen Brawner (brawner@gmail.com) 
     Commit Version: 1.6.0-4-g7f85cfe  Build Version: 1.6.7995.38578
     For more information, please see http://wiki.ros.org/sw_urdf_exporter -->
<robot
  name="collision_model.SLDASM">
  <link
    name="base_link">
    <inertial>
      <origin
        xyz="-7.426E-19 0 0.0127"
        rpy="0 0 0" />
      <mass
        value="0.11583" />
      <inertia
        ixx="4.8264E-05"
        ixy="0"
        ixz="7.8626E-38"
        iyy="4.8264E-05"
        iyz="-1.0831E-37"
        izz="8.4072E-05" />
    </inertial>
    <visual>
      <origin
        xyz="0 0 0"
        rpy="0 0 0" />
      <geometry>
        <mesh
          filename="../robotic-arm-model/meshes/base_link.STL" />
      </geometry>
      <material
        name="">
        <color
          rgba="0.79216 0.81961 0.93333 1" />
      </material>
    </visual>
    <collision>
      <origin
        xyz="0 0 0"
        rpy="0 0 0" />
      <geometry>
        <mesh
          filename="../robotic-arm-model/meshes/base_link.STL" />
      </geometry>
    </collision>
  </link>
  <link
    name="Link1">
    <inertial>
      <origin
        xyz="-9.3441E-11 1.0837E-19 0.11741"
        rpy="0 0 0" />
      <mass
        value="0.48852" />
      <inertia
        ixx="0.00219"
        ixy="-6.4519E-11"
        ixz="2.8597E-11"
        iyy="0.0021648"
        iyz="-1.124E-20"
        izz="0.00018559" />
    </inertial>
    <visual>
      <origin
        xyz="0 0 0"
        rpy="0 0 0" />
      <geometry>
        <mesh
          filename="../robotic-arm-model/meshes/Link1.STL" />
      </geometry>
      <material
        name="">
        <color
          rgba="0.79216 0.81961 0.93333 1" />
      </material>
    </visual>
    <collision>
      <origin
        xyz="0 0 0"
        rpy="0 0 0" />
      <geometry>
        <mesh
          filename="../robotic-arm-model/meshes/Link1.STL" />
      </geometry>
    </collision>
  </link>
  <joint
    name="J1"
    type="revolute">
    <origin
      xyz="0 -0.0254 0"
      rpy="1.5708 -1.5708 0" />
    <parent
      link="base_link" />
    <child
      link="Link1" />
    <axis
      xyz="0 0 1" />
    <limit
      lower="-6.28"
      upper="6.28"
      effort="10"
      velocity="2" />
  </joint>
  <link
    name="Link2">
    <inertial>
      <origin
        xyz="0.1016 9.7469E-18 -0.0127"
        rpy="0 0 0" />
      <mass
        value="0.31367" />
      <inertia
        ixx="8.1553E-05"
        ixy="6.2199E-21"
        ixz="3.6512E-20"
        iyy="0.0015715"
        iyz="3.3938E-22"
        izz="0.0016194" />
    </inertial>
    <visual>
      <origin
        xyz="0 0 0"
        rpy="0 0 0" />
      <geometry>
        <mesh
          filename="../robotic-arm-model/meshes/Link2.STL" />
      </geometry>
      <material
        name="">
        <color
          rgba="0.79216 0.81961 0.93333 1" />
      </material>
    </visual>
    <collision>
      <origin
        xyz="0 0 0"
        rpy="0 0 0" />
      <geometry>
        <mesh
          filename="../robotic-arm-model/meshes/Link2.STL" />
      </geometry>
    </collision>
  </link>
  <joint
    name="J2"
    type="revolute">
    <origin
      xyz="0 0.05842 0.19655"
      rpy="1.5708 -1.5708 0" />
    <parent
      link="Link1" />
    <child
      link="Link2" />
    <axis
      xyz="0 0 1" />
    <limit
      lower="-1.57"
      upper="1.57"
      effort="10"
      velocity="2" />
  </joint>
  <link
    name="Link3">
    <inertial>
      <origin
        xyz="-0.016542 0.023133 -0.0254"
        rpy="0 0 0" />
      <mass
        value="0.30843" />
      <inertia
        ixx="0.00020404"
        ixy="4.3965E-05"
        ixz="-2.7136E-20"
        iyy="0.00027617"
        iyz="1.5599E-20"
        izz="0.00034755" />
    </inertial>
    <visual>
      <origin
        xyz="0 0 0"
        rpy="0 0 0" />
      <geometry>
        <mesh
          filename="../robotic-arm-model/meshes/Link3.STL" />
      </geometry>
      <material
        name="">
        <color
          rgba="0.79216 0.81961 0.93333 1" />
      </material>
    </visual>
    <collision>
      <origin
        xyz="0 0 0"
        rpy="0 0 0" />
      <geometry>
        <mesh
          filename="../robotic-arm-model/meshes/Link3.STL" />
      </geometry>
    </collision>
  </link>
  <joint
    name="J3"
    type="revolute">
    <origin
      xyz="0.2032 0 -0.0254"
      rpy="0 0 -1.5708" />
    <parent
      link="Link2" />
    <child
      link="Link3" />
    <axis
      xyz="0 0 1" />
    <limit
      lower="-3.14"
      upper="1.57"
      effort="10"
      velocity="2" />
  </joint>
  <link
    name="Link4">
    <inertial>
      <origin
        xyz="-0.0046154 -4.6882E-07 0.034316"
        rpy="0 0 0" />
      <mass
        value="0.12125" />
      <inertia
        ixx="9.2966E-05"
        ixy="4.3844E-11"
        ixz="1.7709E-05"
        iyy="9.2332E-05"
        iyz="2.3926E-10"
        izz="3.7485E-05" />
    </inertial>
    <visual>
      <origin
        xyz="0 0 0"
        rpy="0 0 0" />
      <geometry>
        <mesh
          filename="../robotic-arm-model/meshes/Link4.STL" />
      </geometry>
      <material
        name="">
        <color
          rgba="0.79216 0.81961 0.93333 1" />
      </material>
    </visual>
    <collision>
      <origin
        xyz="0 0 0"
        rpy="0 0 0" />
      <geometry>
        <mesh
          filename="../robotic-arm-model/meshes/Link4.STL" />
      </geometry>
    </collision>
  </link>
  <joint
    name="J4"
    type="revolute">
    <origin
      xyz="-0.067818 0.03175 -0.0254"
      rpy="3.1416 -1.5708 0" />
    <parent
      link="Link3" />
    <child
      link="Link4" />
    <axis
      xyz="0 0 1" />
    <limit
      lower="-6.28"
      upper="6.28"
      effort="10"
      velocity="2" />
  </joint>
  <link
    name="Link5">
    <inertial>
      <origin
        xyz="-0.024276 -5.5511E-17 0.009525"
        rpy="0 0 0" />
      <mass
        value="0.033202" />
      <inertia
        ixx="2.7243E-06"
        ixy="-5.5955E-23"
        ixz="-1.3299E-21"
        iyy="1.4161E-05"
        iyz="-6.1182E-24"
        izz="1.4877E-05" />
    </inertial>
    <visual>
      <origin
        xyz="0 0 0"
        rpy="0 0 0" />
      <geometry>
        <mesh
          filename="../robotic-arm-model/meshes/Link5.STL" />
      </geometry>
      <material
        name="">
        <color
          rgba="0.79216 0.81961 0.93333 1" />
      </material>
    </visual>
    <collision>
      <origin
        xyz="0 0 0"
        rpy="0 0 0" />
      <geometry>
        <mesh
          filename="../robotic-arm-model/meshes/Link5.STL" />
      </geometry>
    </collision>
  </link>
  <joint
    name="J5"
    type="revolute">
    <origin
      xyz="-0.01905 0 0.10533"
      rpy="0 1.5708 0" />
    <parent
      link="Link4" />
    <child
      link="Link5" />
    <axis
      xyz="0 0 1" />
    <limit
      lower="-1.57"
      upper="1.57"
      effort="10"
      velocity="2" />
  </joint>
</robot>